<?xml version="1.0"?>
<robot name="myrobot">
 <link name="base_link">
    <visual>
      <origin rpy="0 0 1.5708" xyz="-0.11 -0.2 1.02"/>
      <geometry>
        <mesh filename="package://project_ars/meshes/BodySae1.dae"/>
      </geometry>
    </visual>
     <collision>
      <geometry>
        <mesh filename="package://project_ars/meshes/BodySae1.dae"/>
      </geometry>
      <origin rpy="0 0 1.5708" xyz="-0.11 -0.2 1.02"/>
    </collision>
    <inertial>
      <mass value="10"/>
      <inertia ixx="1e-3" ixy="0.0" ixz="0.0" iyy="1e-3" iyz="0.0" izz="1e-3"/>
    </inertial>
  </link>
  
  <link name="pelvis">
    <visual>
      <origin rpy="0 0 1.5708" xyz="-0.11 -0.2 -0.05"/>
      <geometry>
        <mesh filename="package://project_ars/meshes/PelvisSet.dae"/>
      </geometry>
    </visual>
     <collision>
      <geometry>
        <mesh filename="package://project_ars/meshes/PelvisSet.dae"/>
      </geometry>
      <origin rpy="0 0 1.5708" xyz="-0.11 -0.2 -0.05"/>
    </collision>
    <inertial>
      <mass value="5"/>
      <inertia ixx="1e-3" ixy="0.0" ixz="0.0" iyy="1e-3" iyz="0.0" izz="1e-3"/>
    </inertial>
  </link>
  
  <joint name="base_link_to_pelvis" type="fixed">
    <axis xyz="0 -0.5 0"/>
    <limit effort="1000.0" lower="-0.850" upper="1.3" velocity="0.5"/>
    <parent link="base_link"/>
    <child link="pelvis"/>
    <origin rpy="0 0 0" xyz="0 0 0.92"/>
  </joint>
  
<link name="left_leg">
    <visual>
      <origin rpy="0 0 1.5708" xyz="-0.1 -0.09 -0.88"/>
      <geometry>
        <mesh filename="package://project_ars/meshes/LegSat.dae"/>
      </geometry>
    </visual>
    <collision>
      <geometry>
        <mesh filename="package://project_ars/meshes/LegSat.dae"/>
      </geometry>
      <origin rpy="0 0 1.5708" xyz="-0.1 -0.09 -0.88"/>
    </collision>
    <inertial>
      <mass value="15"/>
      <inertia ixx="1e-3" ixy="0.0" ixz="0.0" iyy="1e-3" iyz="0.0" izz="1e-3"/>
    </inertial>
  </link>
  
  <joint name="pelvis_to_left_leg" type="revolute">
    <axis xyz="0 -0.5 0"/>
    <dynamics damping="0.1" friction="0.0"/>
    <limit effort="50000.0" lower="-0.5" upper="0.850" velocity="0.5"/>
    <parent link="pelvis"/>
    <child link="left_leg"/>
    <origin rpy="0 0 0" xyz="0.1 0.1 -0.05"/>
  </joint>
  
  <link name="right_leg">
    <visual>
      <origin rpy="0 0 1.5708" xyz="-0.1 -0.09 -0.88"/>
      <geometry>
        <mesh filename="package://project_ars/meshes/LegSat.dae"/>
      </geometry>
    </visual>
    <collision>
      <geometry>
        <mesh filename="package://project_ars/meshes/LegSat.dae"/>
      </geometry>
      <origin rpy="0 0 1.5708" xyz="-0.1 -0.09 -0.88"/>
    </collision>
    <inertial>
      <mass value="15"/>
      <inertia ixx="1e-3" ixy="0.0" ixz="0.0" iyy="1e-3" iyz="0.0" izz="1e-3"/>
    </inertial>
  </link>
  
  <joint name="pelvis_to_right_leg" type="revolute">
    <axis xyz="0 -0.5 0"/>
    <dynamics damping="0.1" friction="0.0"/>
    <limit effort="50000.0" lower="-0.5" upper="0.850" velocity="0.5"/>
    <parent link="pelvis"/>
    <child link="right_leg"/>
    <origin rpy="0 0 0" xyz="0.1 -0.1 -0.05"/>
  </joint>
  
  <link name="right_hand">
    <visual>
      <origin rpy="0 0 1.5708" xyz="-0.13 -0.33 -0.9"/>
      <geometry>
        <mesh filename="package://project_ars/meshes/HandSat.dae"/>
      </geometry>
    </visual>
    <collision>
      <geometry>
        <mesh filename="package://project_ars/meshes/HandSat.dae"/>
      </geometry>
      <origin rpy="0 0 1.5708" xyz="-0.13 -0.33 -0.9"/>
    </collision>
    <inertial>
      <mass value="1"/>
      <inertia ixx="1e-3" ixy="0.0" ixz="0.0" iyy="1e-3" iyz="0.0" izz="1e-3"/>
    </inertial>
  </link>
  
  <joint name="base_link_to_right_hand" type="revolute">
    <axis xyz="0 -0.5 0"/>
    <limit effort="500.0" lower="-0.850" upper="3.2" velocity="0.5"/>
    <parent link="base_link"/>
    <child link="right_hand"/>
    <origin rpy="0 0 0" xyz="0.1 -0.15 1.2"/>
  </joint>
  
  <link name="left_hand">
    <visual>
      <origin rpy="0 0 1.5708" xyz="-0.13 -0.33 -0.9"/>
      <geometry>
        <mesh filename="package://project_ars/meshes/HandSat.dae"/>
      </geometry>
    </visual>
    <collision>
      <geometry>
        <mesh filename="package://project_ars/meshes/HandSat.dae"/>
      </geometry>
      <origin rpy="0 0 1.5708" xyz="-0.13 -0.33 -0.9"/>
    </collision>
    <inertial>
      <mass value="1"/>
      <inertia ixx="1e-3" ixy="0.0" ixz="0.0" iyy="1e-3" iyz="0.0" izz="1e-3"/>
    </inertial>
  </link>
  
  <joint name="base_link_to_left_hand" type="revolute">
    <axis xyz="0 0.5 0"/>
    <limit effort="500.0" lower="-0.850" upper="3.2" velocity="0.5"/>
    <parent link="base_link"/>
    <child link="left_hand"/>
    <origin rpy="0 0 3.1416" xyz="0.1 0.15 1.2"/>
  </joint>
  
  <link name="head">
    <visual>
      <origin rpy="0 0 1.5708" xyz="-0.2 -0.15 0"/>
      <geometry>
        <mesh filename="package://project_ars/meshes/HeadSat.dae"/>
      </geometry>
    </visual>
    <collision>
      <geometry>
        <mesh filename="package://project_ars/meshes/HeadSat.dae"/>
      </geometry>
      <origin rpy="0 0 1.5708" xyz="-0.2 -0.15 0"/>
    </collision>
    <inertial>
      <mass value="2"/>
      <inertia ixx="1e-3" ixy="0.0" ixz="0.0" iyy="1e-3" iyz="0.0" izz="1e-3"/>
    </inertial>
  </link>
  
  <joint name="base_link_to_head" type="fixed">
    <axis xyz="0 0 0.5"/>
    <limit effort="500.0" lower="-0.850" upper="0.850" velocity="0.5"/>
    <parent link="base_link"/>
    <child link="head"/>
    <origin rpy="0 0 0" xyz="0.1 0 1.32"/>
  </joint>
</robot>
